Workbook

Sheet Sheet1
A1: 被试 | B1: 任务 | C1: 任务难度 | D1: 情景不稳定性D | E1: 情景复杂性D | F1: 情景变动性D | G1: 觉醒力S | H1: 剩余脑力S | I1: 专注力S | J1: 注意力分割S | K1: 信息数量U | L1: 信息质量U | M1: 情景熟悉度U | N1: SART总分 | O1: Demand合计(D) | P1: Supply合计(S) | Q1: Understanding合计(U)
A2: 1 | B2: 2 | C2: 中 | D2: 1 | E2: 4 | F2: 3 | G2: 3 | H2: 2 | I2: 4 | J2: 4 | K2: 5 | L2: 5 | M2: 4 | N2: =SUM(G2:J2)+SUM(K2:M2)-SUM(D2:F2) -> 19 | O2: =SUM(D2:F2) -> 8 | P2: =SUM(G2:J2) -> 13 | Q2: =SUM(K2:M2) -> 14
A3: 1 | B3: 5_6 | C3: 高 | D3: 4 | E3: 5 | F3: 5 | G3: 4 | H3: 1 | I3: 5 | J3: 5 | K3: 6 | L3: 4 | M3: 3 | N3: =SUM(G3:J3)+SUM(K3:M3)-SUM(D3:F3) -> 14 | O3: =SUM(D3:F3) -> 14 | P3: =SUM(G3:J3) -> 15 | Q3: =SUM(K3:M3) -> 13
A4: 1 | B4: 3 | C4: 低 | D4: 1 | E4: 2 | F4: 2 | G4: 2 | H4: 6 | I4: 4 | J4: 6 | K4: 2 | L4: 2 | M4: 4 | N4: =SUM(G4:J4)+SUM(K4:M4)-SUM(D4:F4) -> 21 | O4: =SUM(D4:F4) -> 5 | P4: =SUM(G4:J4) -> 18 | Q4: =SUM(K4:M4) -> 8
A5: 2 | B5: 1 | C5: 中 | D5: 2 | E5: 3 | F5: 5 | G5: 4 | H5: 5 | I5: 3 | J5: 4 | K5: 4 | L5: 5 | M5: 4 | N5: =SUM(G5:J5)+SUM(K5:M5)-SUM(D5:F5) -> 19 | O5: =SUM(D5:F5) -> 10 | P5: =SUM(G5:J5) -> 16 | Q5: =SUM(K5:M5) -> 13
A6: 2 | B6: 5_6 | C6: 高 | D6: 4 | E6: 3 | F6: 4 | G6: 5 | H6: 3 | I6: 4 | J6: 5 | K6: 4 | L6: 5 | M6: 3 | N6: =SUM(G6:J6)+SUM(K6:M6)-SUM(D6:F6) -> 18 | O6: =SUM(D6:F6) -> 11 | P6: =SUM(G6:J6) -> 17 | Q6: =SUM(K6:M6) -> 12
A7: 2 | B7: 3 | C7: 低 | D7: 2 | E7: 2 | F7: 3 | G7: 3 | H7: 5 | I7: 4 | J7: 4 | K7: 3 | L7: 6 | M7: 5 | N7: =SUM(G7:J7)+SUM(K7:M7)-SUM(D7:F7) -> 23 | O7: =SUM(D7:F7) -> 7 | P7: =SUM(G7:J7) -> 16 | Q7: =SUM(K7:M7) -> 14
A8: 3 | B8: 1 | C8: 中 | D8: 2 | E8: 3 | F8: 2 | G8: 2 | H8: 3 | I8: 3 | J8: 4 | K8: 6 | L8: 5 | M8: 3 | N8: =SUM(G8:J8)+SUM(K8:M8)-SUM(D8:F8) -> 19 | O8: =SUM(D8:F8) -> 7 | P8: =SUM(G8:J8) -> 12 | Q8: =SUM(K8:M8) -> 14
A9: 3 | B9: 4 | C9: 中 | D9: 2 | E9: 2 | F9: 3 | G9: 2 | H9: 3 | I9: 2 | J9: 5 | K9: 5 | L9: 4 | M9: 2 | N9: =SUM(G9:J9)+SUM(K9:M9)-SUM(D9:F9) -> 16 | O9: =SUM(D9:F9) -> 7 | P9: =SUM(G9:J9) -> 12 | Q9: =SUM(K9:M9) -> 11
A10: 3 | B10: 5_6 | C10: 高 | D10: 3 | E10: 3 | F10: 3 | G10: 2 | H10: 4 | I10: 5 | J10: 4 | K10: 5 | L10: 5 | M10: 2 | N10: =SUM(G10:J10)+SUM(K10:M10)-SUM(D10:F10) -> 18 | O10: =SUM(D10:F10) -> 9 | P10: =SUM(G10:J10) -> 15 | Q10: =SUM(K10:M10) -> 12
A11: 4 | B11: 2 | C11: 中 | D11: 3 | E11: 4 | F11: 4 | G11: 5 | H11: 3 | I11: 6 | J11: 6 | K11: 5 | L11: 6 | M11: 4 | N11: =SUM(G11:J11)+SUM(K11:M11)-SUM(D11:F11) -> 24 | O11: =SUM(D11:F11) -> 11 | P11: =SUM(G11:J11) -> 20 | Q11: =SUM(K11:M11) -> 15
A12: 4 | B12: 4 | C12: 中 | D12: 4 | E12: 3 | F12: 5 | G12: 4 | H12: 5 | I12: 5 | J12: 5 | K12: 4 | L12: 4 | M12: 3 | N12: =SUM(G12:J12)+SUM(K12:M12)-SUM(D12:F12) -> 18 | O12: =SUM(D12:F12) -> 12 | P12: =SUM(G12:J12) -> 19 | Q12: =SUM(K12:M12) -> 11
A13: 4 | B13: 5_6 | C13: 高 | D13: 5 | E13: 5 | F13: 6 | G13: 7 | H13: 2 | I13: 6 | J13: 7 | K13: 7 | L13: 6 | M13: 5 | N13: =SUM(G13:J13)+SUM(K13:M13)-SUM(D13:F13) -> 24 | O13: =SUM(D13:F13) -> 16 | P13: =SUM(G13:J13) -> 22 | Q13: =SUM(K13:M13) -> 18
A14: 5 | B14: 1 | C14: 中 | D14: 4 | E14: 3 | F14: 4 | G14: 3 | H14: 3 | I14: 5 | J14: 5 | K14: 6 | L14: 6 | M14: 5 | N14: =SUM(G14:J14)+SUM(K14:M14)-SUM(D14:F14) -> 22 | O14: =SUM(D14:F14) -> 11 | P14: =SUM(G14:J14) -> 16 | Q14: =SUM(K14:M14) -> 17
A15: 5 | B15: 4 | C15: 中 | D15: 5 | E15: 5 | F15: 6 | G15: 4 | H15: 3 | I15: 4 | J15: 5 | K15: 6 | L15: 5 | M15: 4 | N15: =SUM(G15:J15)+SUM(K15:M15)-SUM(D15:F15) -> 15 | O15: =SUM(D15:F15) -> 16 | P15: =SUM(G15:J15) -> 16 | Q15: =SUM(K15:M15) -> 15
A16: 5 | B16: 5_6 | C16: 高 | D16: 5 | E16: 6 | F16: 4 | G16: 4 | H16: 3 | I16: 5 | J16: 5 | K16: 6 | L16: 7 | M16: 6 | N16: =SUM(G16:J16)+SUM(K16:M16)-SUM(D16:F16) -> 21 | O16: =SUM(D16:F16) -> 15 | P16: =SUM(G16:J16) -> 17 | Q16: =SUM(K16:M16) -> 19
A17: 6 | B17: 2 | C17: 中 | D17: 2 | E17: 2 | F17: 2 | G17: 6 | H17: 4 | I17: 5 | J17: 3 | K17: 4 | L17: 5 | M17: 5 | N17: =SUM(G17:J17)+SUM(K17:M17)-SUM(D17:F17) -> 26 | O17: =SUM(D17:F17) -> 6 | P17: =SUM(G17:J17) -> 18 | Q17: =SUM(K17:M17) -> 14
A18: 6 | B18: 5_6 | C18: 高 | D18: 2 | E18: 5 | F18: 2 | G18: 5 | H18: 3 | I18: 6 | J18: 4 | K18: 5 | L18: 4 | M18: 4 | N18: =SUM(G18:J18)+SUM(K18:M18)-SUM(D18:F18) -> 22 | O18: =SUM(D18:F18) -> 9 | P18: =SUM(G18:J18) -> 18 | Q18: =SUM(K18:M18) -> 13
A19: 6 | B19: 3 | C19: 低 | D19: 1 | E19: 1 | F19: 1 | G19: 6 | H19: 5 | I19: 2 | J19: 1 | K19: 2 | L19: 3 | M19: 4 | N19: =SUM(G19:J19)+SUM(K19:M19)-SUM(D19:F19) -> 20 | O19: =SUM(D19:F19) -> 3 | P19: =SUM(G19:J19) -> 14 | Q19: =SUM(K19:M19) -> 9
A20: 7 | B20: 2 | C20: 中 | D20: 6 | E20: 5 | F20: 3 | G20: 5 | H20: 3 | I20: 3 | J20: 4 | K20: 3 | L20: 4 | M20: 4 | N20: =SUM(G20:J20)+SUM(K20:M20)-SUM(D20:F20) -> 12 | O20: =SUM(D20:F20) -> 14 | P20: =SUM(G20:J20) -> 15 | Q20: =SUM(K20:M20) -> 11
A21: 7 | B21: 5_6 | C21: 高 | D21: 5 | E21: 6 | F21: 3 | G21: 4 | H21: 2 | I21: 5 | J21: 4 | K21: 4 | L21: 2 | M21: 5 | N21: =SUM(G21:J21)+SUM(K21:M21)-SUM(D21:F21) -> 12 | O21: =SUM(D21:F21) -> 14 | P21: =SUM(G21:J21) -> 15 | Q21: =SUM(K21:M21) -> 11
A22: 7 | B22: 3 | C22: 低 | D22: 3 | E22: 3 | F22: 2 | G22: 3 | H22: 5 | I22: 5 | J22: 5 | K22: 3 | L22: 4 | M22: 4 | N22: =SUM(G22:J22)+SUM(K22:M22)-SUM(D22:F22) -> 21 | O22: =SUM(D22:F22) -> 8 | P22: =SUM(G22:J22) -> 18 | Q22: =SUM(K22:M22) -> 11
A23: 8 | B23: 1 | C23: 中 | D23: 3 | E23: 3 | F23: 2 | G23: 5 | H23: 3 | I23: 4 | J23: 2 | K23: 3 | L23: 4 | M23: 5 | N23: =SUM(G23:J23)+SUM(K23:M23)-SUM(D23:F23) -> 18 | O23: =SUM(D23:F23) -> 8 | P23: =SUM(G23:J23) -> 14 | Q23: =SUM(K23:M23) -> 12
A24: 8 | B24: 4 | C24: 中 | D24: 2 | E24: 3 | F24: 2 | G24: 5 | H24: 5 | I24: 4 | J24: 1 | K24: 2 | L24: 5 | M24: 5 | N24: =SUM(G24:J24)+SUM(K24:M24)-SUM(D24:F24) -> 20 | O24: =SUM(D24:F24) -> 7 | P24: =SUM(G24:J24) -> 15 | Q24: =SUM(K24:M24) -> 12
A25: 8 | B25: 5_6 | C25: 高 | D25: 4 | E25: 4 | F25: 2 | G25: 5 | H25: 3 | I25: 4 | J25: 3 | K25: 4 | L25: 3 | M25: 5 | N25: =SUM(G25:J25)+SUM(K25:M25)-SUM(D25:F25) -> 17 | O25: =SUM(D25:F25) -> 10 | P25: =SUM(G25:J25) -> 15 | Q25: =SUM(K25:M25) -> 12
A26: 9 | B26: 1 | C26: 中 | D26: 6 | E26: 3 | F26: 4 | G26: 3 | H26: 6 | I26: 5 | J26: 4 | K26: 5 | L26: 5 | M26: 6 | N26: =SUM(G26:J26)+SUM(K26:M26)-SUM(D26:F26) -> 21 | O26: =SUM(D26:F26) -> 13 | P26: =SUM(G26:J26) -> 18 | Q26: =SUM(K26:M26) -> 16
A27: 9 | B27: 4 | C27: 中 | D27: 5 | E27: 4 | F27: 3 | G27: 4 | H27: 5 | I27: 4 | J27: 5 | K27: 4 | L27: 4 | M27: 5 | N27: =SUM(G27:J27)+SUM(K27:M27)-SUM(D27:F27) -> 19 | O27: =SUM(D27:F27) -> 12 | P27: =SUM(G27:J27) -> 18 | Q27: =SUM(K27:M27) -> 13
A28: 9 | B28: 5_6 | C28: 高 | D28: 4 | E28: 7 | F28: 5 | G28: 6 | H28: 3 | I28: 6 | J28: 6 | K28: 5 | L28: 4 | M28: 3 | N28: =SUM(G28:J28)+SUM(K28:M28)-SUM(D28:F28) -> 17 | O28: =SUM(D28:F28) -> 16 | P28: =SUM(G28:J28) -> 21 | Q28: =SUM(K28:M28) -> 12
A29: 10 | B29: 2 | C29: 中 | D29: 2 | E29: 3 | F29: 3 | G29: 3 | H29: 4 | I29: 5 | J29: 5 | K29: 6 | L29: 6 | M29: 4 | N29: =SUM(G29:J29)+SUM(K29:M29)-SUM(D29:F29) -> 25 | O29: =SUM(D29:F29) -> 8 | P29: =SUM(G29:J29) -> 17 | Q29: =SUM(K29:M29) -> 16
A30: 10 | B30: 5_6 | C30: 高 | D30: 2 | E30: 4 | F30: 4 | G30: 5 | H30: 5 | I30: 6 | J30: 6 | K30: 7 | L30: 6 | M30: 4 | N30: =SUM(G30:J30)+SUM(K30:M30)-SUM(D30:F30) -> 29 | O30: =SUM(D30:F30) -> 10 | P30: =SUM(G30:J30) -> 22 | Q30: =SUM(K30:M30) -> 17
A31: 10 | B31: 3 | C31: 低 | D31: 1 | E31: 2 | F31: 2 | G31: 4 | H31: 5 | I31: 4 | J31: 3 | K31: 4 | L31: 5 | M31: 4 | N31: =SUM(G31:J31)+SUM(K31:M31)-SUM(D31:F31) -> 24 | O31: =SUM(D31:F31) -> 5 | P31: =SUM(G31:J31) -> 16 | Q31: =SUM(K31:M31) -> 13
A32: 11 | B32: 1 | C32: 中 | D32: 5 | E32: 5 | F32: 3 | G32: 3 | H32: 4 | I32: 5 | J32: 3 | K32: 5 | L32: 3 | M32: 2 | N32: =SUM(G32:J32)+SUM(K32:M32)-SUM(D32:F32) -> 12 | O32: =SUM(D32:F32) -> 13 | P32: =SUM(G32:J32) -> 15 | Q32: =SUM(K32:M32) -> 10
A33: 11 | B33: 5_6 | C33: 高 | D33: 5 | E33: 5 | F33: 4 | G33: 4 | H33: 2 | I33: 4 | J33: 3 | K33: 4 | L33: 3 | M33: 3 | N33: =SUM(G33:J33)+SUM(K33:M33)-SUM(D33:F33) -> 9 | O33: =SUM(D33:F33) -> 14 | P33: =SUM(G33:J33) -> 13 | Q33: =SUM(K33:M33) -> 10
A34: 11 | B34: 3 | C34: 低 | D34: 5 | E34: 4 | F34: 3 | G34: 4 | H34: 3 | I34: 5 | J34: 3 | K34: 4 | L34: 3 | M34: 2 | N34: =SUM(G34:J34)+SUM(K34:M34)-SUM(D34:F34) -> 12 | O34: =SUM(D34:F34) -> 12 | P34: =SUM(G34:J34) -> 15 | Q34: =SUM(K34:M34) -> 9
A35: 12 | B35: 2 | C35: 中 | D35: 2 | E35: 1 | F35: 2 | G35: 4 | H35: 5 | I35: 3 | J35: 6 | K35: 4 | L35: 4 | M35: 7 | N35: =SUM(G35:J35)+SUM(K35:M35)-SUM(D35:F35) -> 28 | O35: =SUM(D35:F35) -> 5 | P35: =SUM(G35:J35) -> 18 | Q35: =SUM(K35:M35) -> 15
A36: 12 | B36: 5_6 | C36: 高 | D36: 6 | E36: 7 | F36: 5 | G36: 6 | H36: 3 | I36: 4 | J36: 6 | K36: 6 | L36: 4 | M36: 5 | N36: =SUM(G36:J36)+SUM(K36:M36)-SUM(D36:F36) -> 16 | O36: =SUM(D36:F36) -> 18 | P36: =SUM(G36:J36) -> 19 | Q36: =SUM(K36:M36) -> 15
A37: 12 | B37: 3 | C37: 低 | D37: 1 | E37: 1 | F37: 2 | G37: 5 | H37: 6 | I37: 5 | J37: 2 | K37: 3 | L37: 5 | M37: 4 | N37: =SUM(G37:J37)+SUM(K37:M37)-SUM(D37:F37) -> 26 | O37: =SUM(D37:F37) -> 4 | P37: =SUM(G37:J37) -> 18 | Q37: =SUM(K37:M37) -> 12
A38: 13 | B38: 5_6 | C38: 高 | D38: 5 | E38: 4 | F38: 5 | G38: 1 | H38: 1 | I38: 4 | J38: 5 | K38: 4 | L38: 2 | M38: 2 | N38: =SUM(G38:J38)+SUM(K38:M38)-SUM(D38:F38) -> 5 | O38: =SUM(D38:F38) -> 14 | P38: =SUM(G38:J38) -> 11 | Q38: =SUM(K38:M38) -> 8
A39: 13 | B39: 3 | C39: 低 | D39: 2 | E39: 1 | F39: 2 | G39: 4 | H39: 4 | I39: 2 | J39: 2 | K39: 2 | L39: 3 | M39: 4 | N39: =SUM(G39:J39)+SUM(K39:M39)-SUM(D39:F39) -> 16 | O39: =SUM(D39:F39) -> 5 | P39: =SUM(G39:J39) -> 12 | Q39: =SUM(K39:M39) -> 9
A40: 13 | B40: 5 | C40: 低 | D40: 1 | E40: 2 | F40: 1 | G40: 2 | H40: 4 | I40: 4 | J40: 1 | K40: 1 | L40: 4 | M40: 3 | N40: =SUM(G40:J40)+SUM(K40:M40)-SUM(D40:F40) -> 15 | O40: =SUM(D40:F40) -> 4 | P40: =SUM(G40:J40) -> 11 | Q40: =SUM(K40:M40) -> 8
...

Sheet 计算说明
A1: SART总分计算说明
A3: 项目 | B3: 说明
A4: Demand(D) | B4: 情景不稳定性D + 情景复杂性D + 情景变动性D
A5: Supply(S) | B5: 觉醒力S + 剩余脑力S + 专注力S + 注意力分割S
A6: Understanding(U) | B6: 信息数量U + 信息质量U + 情景熟悉度U
A7: SART总分 | B7: Supply(S) + Understanding(U) - Demand(D)
A8: 数据范围 | B8: Sheet1!A1:Q83；SART总分位于 Sheet1!N 列，三个分量位于 O:Q 列

Sheet 难度汇总
A1: 任务难度 | B1: 样本量 | C1: SART总分均值 | D1: 标准差 | E1: 最小值 | F1: 最大值
A2: 低 | B2: =COUNTIF(Sheet1!$C$2:$C$83,A2) -> 30 | C2: =AVERAGEIF(Sheet1!$C$2:$C$83,A2,Sheet1!$N$2:$N$83) -> 21.266667 | D2: 4.5100144 | E2: 12 | F2: 31
A3: 中 | B3: =COUNTIF(Sheet1!$C$2:$C$83,A3) -> 24 | C3: =AVERAGEIF(Sheet1!$C$2:$C$83,A3,Sheet1!$N$2:$N$83) -> 19.75 | D3: 4.6461765 | E3: 12 | F3: 29
A4: 高 | B4: =COUNTIF(Sheet1!$C$2:$C$83,A4) -> 28 | C4: =AVERAGEIF(Sheet1!$C$2:$C$83,A4,Sheet1!$N$2:$N$83) -> 16.714286 | D4: 5.3184316 | E4: 5 | F4: 29
